Workbook

Sheet How to use
A1: ECFD Egyptian Call Lexicon
A2: The words Egyptians actually use on the phone: Arabized English verbs (اتشيك، كنسل)، slang, request verbs, secret objects, scam phrases.
A4: What it is used for
A5: 1. NLP detection: one entry per stem; the matcher strips Arabic prefixes/suffixes (ه، ب، ات … ها، لي، هولي) so كنسل also catches هكنسلهالك.
A6: 2. ASR testing: every Example sentence is a line to record (Test 1 / bake-off).
A7: 3. ASR fine-tuning: the example sentences + recordings become training data.
A9: How to add or check words (yellow cells are for you)
A10: • Add a new row at the bottom of the Lexicon tab. Fill Word, Other spellings, Meaning, Category, Risk role, Said by, Example sentence, Added by.
A11: • Every row starts as 'Claude draft'. A native speaker changes Status to 'Verified' (or 'Rejected' / 'Needs discussion').
A12: • Other spellings: every way the ASR might write it - Arabic script, Latin, with/without ال. Separate with |
A13: • Example sentence: how a real person would say it on a call - not formal Arabic.
A14: • Rows marked 'verify' in Notes (mostly money slang) are ones Claude is unsure about.
... A24: Legend: yellow cells = to fill in / verify

Sheet Lexicon
A1: ID | B1: Word (as spoken) | C1: Other spellings (| separated) | D1: Meaning (English) | E1: Category | F1: Concept | G1: Risk role | H1: Said by | I1: Example sentence (Egyptian) | J1: Status | K1: Added by | L1: Notes
A2: L001 | B2: اتشيك | C2: شيّك|هشيّك|بشيّك|اتشيكلك|مشيّك | D2: check | E2: Arabized English verb | F2: CHECK | G2: NEUTRAL | H2: Both | I2: ثواني اتشيك لحضرتك | J2: Claude draft | K2: Claude | L2: شيك can also mean a bank cheque (شيك بنكي) - context decides
A3: L002 | B3: كنسل | C3: هكنسل|كنسلها|اتكنسل|ماتكنسلش|هكنسلهالك | D3: cancel | E3: Arabized English verb | F3: CANCEL | G3: SCORE | H3: Both | I3: هكنسلهالك من عندي بس محتاج الكود | J3: Claude draft | K3: Claude
A4: L003 | B4: فورود | C4: فورودهولي|فوروردلي|اعمل فورورد|فوروردها | D4: forward | E4: Arabized English verb | F4: FORWARD | G4: HARD | H4: Caller | I4: فورودهولي الرسالة اللي جاتلك | J4: Claude draft | K4: Claude | L4: forwarding an SMS = sharing the OTP
A5: L004 | B5: سيّف | C5: سيفها|اعمل سيف|متسيّفة | D5: save | E5: Arabized English verb | F5: SAVE | G5: NEUTRAL | H5: Both | I5: سيّف الرقم ده عندك | J5: Claude draft | K5: Claude
A6: L005 | B6: شيّر | C6: اعمل شير|شيرلي|شيّر الشاشة|شير سكرين | D6: share | E6: Arabized English verb | F6: SHARE | G6: HARD | H6: Caller | I6: اعمل شير سكرين عشان أشوف المشكلة | J6: Claude draft | K6: Claude | L6: screen share = remote access
A7: L006 | B7: داونلود | C7: نزّل|اعمل داونلود|داونلودها | D7: download | E7: Arabized English verb | F7: INSTALL | G7: HARD | H7: Caller | I7: اعمل داونلود للأبلكيشن ده | J7: Claude draft | K7: Claude
A8: L007 | B8: ابلود | C8: اعمل ابلود|ابلودها | D8: upload | E8: Arabized English verb | F8: UPLOAD | G8: SCORE | H8: Caller | I8: ابلود صورة البطاقة هنا | J8: Claude draft | K8: Claude | L8: ID photo upload
A9: L008 | B9: انستول | C9: اعمل انستول|انستولها|سطّب|سطّبها | D9: install | E9: Arabized English verb | F9: INSTALL | G9: HARD | H9: Caller | I9: سطّب البرنامج ده وانا هكمل معاك | J9: Claude draft | K9: Claude
A10: L009 | B10: اكسبت | C10: اعمل اكسبت|اكسبتها|دوس اكسبت | D10: accept | E10: Arabized English verb | F10: APPROVE | G10: HARD | H10: Caller | I10: هيجيلك طلب دوس اكسبت | J10: Claude draft | K10: Claude
A11: L010 | B11: كونفيرم | C11: اعمل كونفيرم|كونفرم|كونفيرمها | D11: confirm | E11: Arabized English verb | F11: APPROVE | G11: HARD | H11: Caller | I11: دوس كونفيرم عشان العملية تخلص | J11: Claude draft | K11: Claude
A12: L011 | B12: أبروف | C12: ابروف|اعمل ابروف|ابروفها | D12: approve | E12: Arabized English verb | F12: APPROVE | G12: HARD | H12: Caller | I12: اعمل أبروف للعملية اللي هتظهرلك | J12: Claude draft | K12: Claude
A13: L012 | B13: ابديت | C13: اعمل ابديت|أبديت|ابديتها|اتأبدت | D13: update | E13: Arabized English verb | F13: UPDATE_DATA | G13: SCORE | H13: Caller | I13: لازم نعمل ابديت لبياناتك النهارده | J13: Claude draft | K13: Claude
A14: L013 | B14: ريست | C14: ريسيت|اعمل ريست|ريستها | D14: reset | E14: Arabized English verb | F14: RESET | G14: SCORE | H14: Both | I14: هعملك ريست للباسورد | J14: Claude draft | K14: Claude
A15: L014 | B15: ريستارت | C15: اعمل ريستارت|ريستارتها | D15: restart | E15: Arabized English verb | F15: RESTART | G15: NEUTRAL | H15: Both | I15: اعمل ريستارت للموبايل | J15: Claude draft | K15: Claude
A16: L015 | B16: فورمات | C16: اعمل فورمات|فرمت|اتفرمت | D16: format (wipe) | E16: Arabized English verb | F16: FORMAT | G16: NEUTRAL | H16: Both | I16: الموبايل محتاج فورمات | J16: Claude draft | K16: Claude
A17: L016 | B17: لوج إن | C17: لوجين|اعمل لوج ان|لوج اوت | D17: log in / log out | E17: Arabized English verb | F17: LOGIN | G17: SCORE | H17: Caller | I17: اعمل لوج إن بالأكونت بتاعك وانا معاك | J17: Claude draft | K17: Claude
A18: L017 | B18: ساين إن | C18: ساين ان|ساين أب|ساين اب | D18: sign in / sign up | E18: Arabized English verb | F18: LOGIN | G18: SCORE | H18: Caller | I18: اعمل ساين إن تاني | J18: Claude draft | K18: Claude
A19: L018 | B19: سكان | C19: اعمل سكان|سكانها | D19: scan | E19: Arabized English verb | F19: SCAN | G19: SCORE | H19: Caller | I19: اعمل سكان للكيو آر كود ده | J19: Claude draft | K19: Claude | L19: QR scam
A20: L019 | B20: كوبي | C20: اعمل كوبي|كوبي بيست|بيست | D20: copy / paste | E20: Arabized English verb | F20: COPY | G20: SCORE | H20: Caller | I20: اعمل كوبي للكود وابعتهولي | J20: Claude draft | K20: Claude
A21: L020 | B21: سيند | C21: اعمل سيند|سيندها | D21: send | E21: Arabized English verb | F21: SEND | G21: SCORE | H21: Caller | I21: دوس سيند | J21: Claude draft | K21: Claude
A22: L021 | B22: ديليت | C22: امسح|اعمل ديليت|ديليتها | D22: delete | E22: Arabized English verb | F22: DELETE | G22: SCORE | H22: Caller | I22: اعمل ديليت للرسالة بعد ما تبعتها | J22: Claude draft | K22: Claude | L22: hiding traces
A23: L022 | B23: بلوك | C23: اعمل بلوك|اتبلك|اتبلوك|انبلوك | D23: block / unblock | E23: Arabized English verb | F23: BLOCK | G23: SCORE | H23: Caller | I23: الكارت هيتعمله بلوك لو ماأكدتش | J23: Claude draft | K23: Claude
A24: L023 | B24: فعّل | C24: اكتيف|اعمل اكتيفيت|اتفعّل|تفعيل | D24: activate | E24: Arabized English verb | F24: ACTIVATE | G24: SCORE | H24: Caller | I24: محتاجين نفعّل الخدمة دلوقتي | J24: Claude draft | K24: Claude
A25: L024 | B25: فيرفاي | C25: فريفاي|اعمل فيرفاي|فيرفيكيشن | D25: verify | E25: Arabized English verb | F25: VERIFY | G25: SCORE | H25: Caller | I25: محتاج أعمل فيرفاي للأكونت | J25: Claude draft | K25: Claude
A26: L025 | B26: هاك | C26: اتهكر|اتهاك|هكر|هاكر | D26: hack / hacked | E26: Arabized English verb | F26: HACKED | G26: SCORE | H26: Caller | I26: حسابك اتهكر ولازم نأمنه | J26: Claude draft | K26: Claude | L26: fear pretext
A27: L026 | B27: فريز | C27: اتعمله فريز|تجميد|اتجمّد | D27: freeze | E27: Arabized English verb | F27: FREEZE | G27: SCORE | H27: Caller | I27: الحساب هيتعمله فريز النهارده | J27: Claude draft | K27: Claude
A28: L027 | B28: سبسكرايب | C28: اشترك|اتشترك|سبسكرايب | D28: subscribe | E28: Arabized English verb | F28: SUBSCRIBE | G28: NEUTRAL | H28: Both | I28: انت مشترك في خدمة جديدة | J28: Claude draft | K28: Claude
A29: L028 | B29: ريفاند | C29: استرداد|رجّع الفلوس|ريفند | D29: refund | E29: Arabized English verb | F29: REFUND | G29: SCORE | H29: Caller | I29: هنعملك ريفاند بس محتاجين بيانات الكارت | J29: Claude draft | K29: Claude | L29: refund pretext
A30: L029 | B30: شارج | C30: اشحن|شحن|اشحنلي | D30: charge / top up | E30: Arabized English verb | F30: TOP_UP | G30: SCORE | H30: Caller | I30: اشحنلي كارت بمية جنيه | J30: Claude draft | K30: Claude
A31: L030 | B31: رن | C31: رنّلي|ارن|رنة|اديني رنة | D31: ring (missed call) | E31: Arabized English verb | F31: CALL | G31: NEUTRAL | H31: Both | I31: اديني رنة على الرقم ده | J31: Claude draft | K31: Claude
A32: L031 | B32: كول | C32: اعمل كول|فويس كول|فيديو كول | D32: call | E32: Arabized English verb | F32: CALL | G32: NEUTRAL | H32: Both | I32: هعملك كول تاني بعد شوية | J32: Claude draft | K32: Claude
A33: L032 | B33: ريبلاي | C33: رد|اعمل ريبلاي | D33: reply | E33: Arabized English verb | F33: REPLY | G33: NEUTRAL | H33: Both | I33: اعمل ريبلاي على الرسالة بكلمة نعم | J33: Claude draft | K33: Claude
A34: L033 | B34: كليك | C34: اضغط|دوس|اعمل كليك | D34: click | E34: Arabized English verb | F34: CLICK | G34: SCORE | H34: Caller | I34: دوس على اللينك اللي جالك | J34: Claude draft | K34: Claude
A35: L034 | B35: سيت أب | C35: اعمل سيت اب|سيتاب | D35: set up | E35: Arabized English verb | F35: SETUP | G35: NEUTRAL | H35: Both | I35: هعملك سيت أب للأبلكيشن | J35: Claude draft | K35: Claude
A36: L035 | B36: فولو أب | C36: فولو اب|هتابع|متابعة | D36: follow up | E36: Arabized English verb | F36: FOLLOW_UP | G36: NEUTRAL | H36: Both | I36: هعمل فولو أب مع حضرتك بكرة | J36: Claude draft | K36: Claude
A37: L036 | B37: بوك | C37: احجز|اعمل بوكينج|بوكينج | D37: book | E37: Arabized English verb | F37: BOOK | G37: NEUTRAL | H37: Both | I37: احجزلك ميعاد في الفرع | J37: Claude draft | K37: Claude
A38: L037 | B38: لينك | C38: اللينك|لينكات|رابط | D38: link | E38: English loanword / tech term | F38: LINK | G38: HARD | H38: Caller | I38: هبعتلك لينك افتحه ودخل بياناتك | J38: Claude draft | K38: Claude | L38: link + enter data = phishing
A39: L038 | B39: أبلكيشن | C39: ابلكيشن|ابليكيشن|الابلكيشن|التطبيق|أبلكيشن | D39: application (app) | E39: English loanword / tech term | F39: APP | G39: SCORE | H39: Both | I39: نزّل الأبلكيشن ده من اللينك | J39: Claude draft | K39: Claude
A40: L039 | B40: الأكونت | C40: اكونت|اكاونت|الاكاونت|حساب | D40: account | E40: English loanword / tech term | F40: ACCOUNT | G40: SCORE | H40: Both | I40: الأكونت بتاعك عليه مشكلة | J40: Claude draft | K40: Claude
...

Sheet Summary
A1: Lexicon summary (live counts from the Lexicon tab)
A3: Category | B3: Words | C3: Verified
A4: Address term / rapport | B4: =COUNTIF(Lexicon!$E$2:$E$1000,A4) | C4: =COUNTIFS(Lexicon!$E$2:$E$1000,A4,Lexicon!$J$2:$J$1000,"Verified")
A5: Arabized English verb | B5: =COUNTIF(Lexicon!$E$2:$E$1000,A5) | C5: =COUNTIFS(Lexicon!$E$2:$E$1000,A5,Lexicon!$J$2:$J$1000,"Verified")
A6: Claimed identity / authority | B6: =COUNTIF(Lexicon!$E$2:$E$1000,A6) | C6: =COUNTIFS(Lexicon!$E$2:$E$1000,A6,Lexicon!$J$2:$J$1000,"Verified")
A7: English loanword / tech term | B7: =COUNTIF(Lexicon!$E$2:$E$1000,A7) | C7: =COUNTIFS(Lexicon!$E$2:$E$1000,A7,Lexicon!$J$2:$J$1000,"Verified")
A8: Everyday Egyptian | B8: =COUNTIF(Lexicon!$E$2:$E$1000,A8) | C8: =COUNTIFS(Lexicon!$E$2:$E$1000,A8,Lexicon!$J$2:$J$1000,"Verified")
A9: Money & payment | B9: =COUNTIF(Lexicon!$E$2:$E$1000,A9) | C9: =COUNTIFS(Lexicon!$E$2:$E$1000,A9,Lexicon!$J$2:$J$1000,"Verified")
A10: Pressure & secrecy | B10: =COUNTIF(Lexicon!$E$2:$E$1000,A10) | C10: =COUNTIFS(Lexicon!$E$2:$E$1000,A10,Lexicon!$J$2:$J$1000,"Verified")
A11: Request verb | B11: =COUNTIF(Lexicon!$E$2:$E$1000,A11) | C11: =COUNTIFS(Lexicon!$E$2:$E$1000,A11,Lexicon!$J$2:$J$1000,"Verified")
A12: Scam pretext / phrase | B12: =COUNTIF(Lexicon!$E$2:$E$1000,A12) | C12: =COUNTIFS(Lexicon!$E$2:$E$1000,A12,Lexicon!$J$2:$J$1000,"Verified")
A13: Secret object | B13: =COUNTIF(Lexicon!$E$2:$E$1000,A13) | C13: =COUNTIFS(Lexicon!$E$2:$E$1000,A13,Lexicon!$J$2:$J$1000,"Verified")
A14: Spoken numbers | B14: =COUNTIF(Lexicon!$E$2:$E$1000,A14) | C14: =COUNTIFS(Lexicon!$E$2:$E$1000,A14,Lexicon!$J$2:$J$1000,"Verified")
A15: Total | B15: =SUM(B4:B14) | C15: =SUM(C4:C14)
A17: Risk role | B17: Words
A18: HARD | B18: =COUNTIF(Lexicon!$G$2:$G$1000,A18)
A19: SCORE | B19: =COUNTIF(Lexicon!$G$2:$G$1000,A19)
A20: CONTEXT | B20: =COUNTIF(Lexicon!$G$2:$G$1000,A20)
A21: NEUTRAL | B21: =COUNTIF(Lexicon!$G$2:$G$1000,A21)
A23: Verified so far | B23: =IFERROR(C15/B15,0)

Sheet Transcription guide
A1: Transcription guideline (use the same rules for every recording)
A2: Rule | B2: Example
A3: Write Egyptian as spoken - never convert to formal Arabic | B3: عايز (not أريد)، دلوقتي (not الآن)
A4: English acronyms and brand names in Latin letters | B4: OTP, CVV, PIN, IT, AnyDesk, InstaPay
A5: ال attached to an English word: keep it attached, as spoken | B5: الcvv، الotp
A6: Arabized English verbs in Arabic letters, as pronounced | B6: اتشيك، هكنسلهالك، فورودهولي
A7: English nouns Egyptians use every day in Arabic letters | B7: الباسورد، اللينك، الأبلكيشن، الأكونت
A8: Digits spoken one by one: write each as a digit | B8: صفر واحد خمسة -> 0 1 5
A9: Keep Egyptian ج/ق as heard | B9: جالك (not قالك)
A10: Don't add punctuation you didn't hear; no diacritics
A11: Unclear word: write [?] - never guess | B11: ابعتلي [?] بسرعة
